<?xml version="1.0"?>
<robot xmlns:xacro="http://www.ros.org/wiki/xacro" name="agv_robot">
  <!-- Geometry parameters -->
  <xacro:property name="base_length" value="0.320"/>
  <xacro:property name="base_width" value="0.240"/>
  <xacro:property name="base_height" value="0.090"/>
  <xacro:property name="wheel_radius" value="0.065"/>
  <xacro:property name="wheel_width" value="0.030"/>
  <xacro:property name="wheel_separation" value="0.170"/>
  <xacro:property name="caster_radius" value="0.025"/>

  <!-- Mass parameters -->
  <xacro:property name="base_mass" value="3.0"/>
  <xacro:property name="wheel_mass" value="0.20"/>
  <xacro:property name="caster_mass" value="0.05"/>

  <xacro:macro name="box_inertia" params="mass x y z">
    <inertial>
      <mass value="${mass}"/>
      <origin xyz="0 0 0" rpy="0 0 0"/>
      <inertia
        ixx="${mass * (y*y + z*z) / 12.0}"
        ixy="0"
        ixz="0"
        iyy="${mass * (x*x + z*z) / 12.0}"
        iyz="0"
        izz="${mass * (x*x + y*y) / 12.0}"/>
    </inertial>
  </xacro:macro>

  <xacro:macro name="cylinder_inertia" params="mass radius length">
    <inertial>
      <mass value="${mass}"/>
      <origin xyz="0 0 0" rpy="0 0 0"/>
      <inertia
        ixx="${mass * (3.0 * radius * radius + length * length) / 12.0}"
        ixy="0"
        ixz="0"
        iyy="${mass * radius * radius / 2.0}"
        iyz="0"
        izz="${mass * (3.0 * radius * radius + length * length) / 12.0}"/>
    </inertial>
  </xacro:macro>

  <material name="body_blue">
    <color rgba="0.05 0.22 0.55 1.0"/>
  </material>

  <material name="wheel_black">
    <color rgba="0.02 0.02 0.02 1.0"/>
  </material>

  <material name="sensor_gray">
    <color rgba="0.35 0.35 0.35 1.0"/>
  </material>

  <link name="base_footprint"/>

  <joint name="base_footprint_to_base_link" type="fixed">
    <parent link="base_footprint"/>
    <child link="base_link"/>
    <origin xyz="0 0 ${wheel_radius}" rpy="0 0 0"/>
  </joint>

  <link name="base_link">
    <visual>
      <origin xyz="0 0 ${base_height / 2.0}" rpy="0 0 0"/>
      <geometry>
        <box size="${base_length} ${base_width} ${base_height}"/>
      </geometry>
      <material name="body_blue"/>
    </visual>
    <collision>
      <origin xyz="0 0 ${base_height / 2.0}" rpy="0 0 0"/>
      <geometry>
        <box size="${base_length} ${base_width} ${base_height}"/>
      </geometry>
    </collision>
    <xacro:box_inertia mass="${base_mass}" x="${base_length}" y="${base_width}" z="${base_height}"/>
  </link>

  <xacro:macro name="drive_wheel" params="prefix y">
    <link name="${prefix}_wheel_link">
      <visual>
        <origin xyz="0 0 0" rpy="${pi / 2.0} 0 0"/>
        <geometry>
          <cylinder radius="${wheel_radius}" length="${wheel_width}"/>
        </geometry>
        <material name="wheel_black"/>
      </visual>
      <collision>
        <origin xyz="0 0 0" rpy="${pi / 2.0} 0 0"/>
        <geometry>
          <cylinder radius="${wheel_radius}" length="${wheel_width}"/>
        </geometry>
      </collision>
      <xacro:cylinder_inertia mass="${wheel_mass}" radius="${wheel_radius}" length="${wheel_width}"/>
    </link>

    <joint name="${prefix}_wheel_joint" type="continuous">
      <parent link="base_link"/>
      <child link="${prefix}_wheel_link"/>
      <origin xyz="0 ${y} 0" rpy="0 0 0"/>
      <axis xyz="0 1 0"/>
    </joint>
  </xacro:macro>

  <xacro:drive_wheel prefix="left" y="${wheel_separation / 2.0}"/>
  <xacro:drive_wheel prefix="right" y="${-wheel_separation / 2.0}"/>

  <link name="caster_link">
    <visual>
      <origin xyz="0 0 0" rpy="0 0 0"/>
      <geometry>
        <sphere radius="${caster_radius}"/>
      </geometry>
      <material name="wheel_black"/>
    </visual>
    <collision>
      <origin xyz="0 0 0" rpy="0 0 0"/>
      <geometry>
        <sphere radius="${caster_radius}"/>
      </geometry>
    </collision>
    <inertial>
      <mass value="${caster_mass}"/>
      <origin xyz="0 0 0" rpy="0 0 0"/>
      <inertia
        ixx="${2.0 * caster_mass * caster_radius * caster_radius / 5.0}"
        ixy="0"
        ixz="0"
        iyy="${2.0 * caster_mass * caster_radius * caster_radius / 5.0}"
        iyz="0"
        izz="${2.0 * caster_mass * caster_radius * caster_radius / 5.0}"/>
    </inertial>
  </link>

  <joint name="caster_joint" type="fixed">
    <parent link="base_link"/>
    <child link="caster_link"/>
    <origin xyz="-0.115 0 ${caster_radius - wheel_radius}" rpy="0 0 0"/>
  </joint>

  <link name="imu_link"/>

  <joint name="imu_joint" type="fixed">
    <parent link="base_link"/>
    <child link="imu_link"/>
    <origin xyz="0 0 ${base_height + 0.010}" rpy="0 0 0"/>
  </joint>

  <link name="base_laser">
    <visual>
      <origin xyz="0 0 0" rpy="0 0 0"/>
      <geometry>
        <cylinder radius="0.035" length="0.030"/>
      </geometry>
      <material name="sensor_gray"/>
    </visual>
    <collision>
      <origin xyz="0 0 0" rpy="0 0 0"/>
      <geometry>
        <cylinder radius="0.035" length="0.030"/>
      </geometry>
    </collision>
    <xacro:cylinder_inertia mass="0.10" radius="0.035" length="0.030"/>
  </link>

  <joint name="laser_joint" type="fixed">
    <parent link="base_link"/>
    <child link="base_laser"/>
    <origin xyz="0.070 0 ${base_height + 0.025}" rpy="0 0 0"/>
  </joint>
</robot>
